<?xml version="1.0" encoding="utf-8"?>
<!-- This URDF was automatically created by SolidWorks to URDF Exporter! Originally created by Stephen Brawner (brawner@gmail.com) 
     Commit Version: 1.6.0-1-g15f4949  Build Version: 1.6.7594.29634
     For more information, please see http://wiki.ros.org/sw_urdf_exporter -->
<robot
  name="arm_assembly_6">
  <link
    name="dummy_link">
  </link>
  <link
    name="base_link">
    <inertial>
      <origin
        xyz="0.018792 0.01999 -0.010001"
        rpy="0 0 0" />
      <mass
        value="0.031905" />
      <inertia
        ixx="5.4828E-06"
        ixy="8.0892E-08"
        ixz="9.1152E-11"
        iyy="5.2647E-06"
        iyz="-2.6656E-10"
        izz="8.6771E-06" />
    </inertial>
    <visual>
      <origin
        xyz="0 0 0"
        rpy="0 0 0" />
      <geometry>
        <mesh
          filename="package://arm_assembly_6/meshes/base_link.STL" />
      </geometry>
      <material
        name="">
        <color
          rgba="0.79216 0.81961 0.93333 1" />
      </material>
    </visual>
    <collision>
      <origin
        xyz="0 0 0"
        rpy="0 0 0" />
      <geometry>
        <mesh
          filename="package://arm_assembly_6/meshes/base_link.STL" />
      </geometry>
    </collision>
  </link>
  <joint
    name="dummy_joint"
    type="fixed">
    <parent
      link="dummy_link"/>
    <child
      link="base_link"/>
  </joint>
  <link
    name="link1">
    <inertial>
      <origin
        xyz="0.0086911 0.0060945 0.027002"
        rpy="1.57 1.57 0" />
      <mass
        value="0.04101" />
      <inertia
        ixx="9.4621E-06"
        ixy="-3.7028E-07"
        ixz="-5.3537E-07"
        iyy="9.1864E-06"
        iyz="-5.2348E-07"
        izz="1.2798E-05" />
    </inertial>
    <visual>
      <origin
        xyz="0 0 0"
        rpy="0 0 0" />
      <geometry>
        <mesh
          filename="package://arm_assembly_6/meshes/link1.STL" />
      </geometry>
      <material
        name="">
        <color
          rgba="0.79216 0.81961 0.93333 1" />
      </material>
    </visual>
    <collision>
      <origin
        xyz="0 0 0"
        rpy="0 0 0" />
      <geometry>
        <mesh
          filename="package://arm_assembly_6/meshes/link1.STL" />
      </geometry>
    </collision>
  </link>
  <joint
    name="joint1"
    type="revolute">
    <origin
      xyz="0.043 0.010099 -0.010156"
      rpy="-1.5708 1.567 -1.5708" />
    <parent
      link="base_link" />
    <child
      link="link1" />
    <axis
      xyz="0 0 1" />
    <limit
      lower="0"
      upper="3.1415"
      effort="0"
      velocity="0" />
  </joint>
  <link
    name="link2">
    <inertial>
      <origin
        xyz="-0.0035099 0.043261 0.034631"
        rpy="0 0 0" />
      <mass
        value="0.044197" />
      <inertia
        ixx="3.3374E-05"
        ixy="1.0834E-06"
        ixz="5.9798E-07"
        iyy="1.2428E-05"
        iyz="-7.3005E-06"
        izz="2.4892E-05" />
    </inertial>
    <visual>
      <origin
        xyz="0 0 0"
        rpy="0 0 0" />
      <geometry>
        <mesh
          filename="package://arm_assembly_6/meshes/link2.STL" />
      </geometry>
      <material
        name="">
        <color
          rgba="0.79216 0.81961 0.93333 1" />
      </material>
    </visual>
    <collision>
      <origin
        xyz="0 0 0"
        rpy="0 0 0" />
      <geometry>
        <mesh
          filename="package://arm_assembly_6/meshes/link2.STL" />
      </geometry>
    </collision>
  </link>
  <joint
    name="joint2"
    type="revolute">
    <origin
      xyz="-0.00052573 0.032998 0.027656"
      rpy="-1.5746 -1.5708 0" />
    <parent
      link="link1" />
    <child
      link="link2" />
    <axis
      xyz="0 0 1" />
    <limit
      lower="-1.5708"
      upper="1.5708"
      effort="0"
      velocity="0" />
  </joint>
  <link
    name="link3">
    <inertial>
      <origin
        xyz="-0.0013502 -0.0048384 0.040737"
        rpy="0 0 0" />
      <mass
        value="0.046897" />
      <inertia
        ixx="2.1054E-05"
        ixy="-7.094E-07"
        ixz="3.5074E-07"
        iyy="1.9131E-05"
        iyz="9.6626E-07"
        izz="1.3945E-05" />
    </inertial>
    <visual>
      <origin
        xyz="0 0 0"
        rpy="0 0 0" />
      <geometry>
        <mesh
          filename="package://arm_assembly_6/meshes/link3.STL" />
      </geometry>
      <material
        name="">
        <color
          rgba="0.79216 0.81961 0.93333 1" />
      </material>
    </visual>
    <collision>
      <origin
        xyz="0 0 0"
        rpy="0 0 0" />
      <geometry>
        <mesh
          filename="package://arm_assembly_6/meshes/link3.STL" />
      </geometry>
    </collision>
  </link>
  <joint
    name="joint3"
    type="revolute">
    <origin
      xyz="-0.0035812 0.076462 0.028599"
      rpy="-1.5708 0 0.012103" />
    <parent
      link="link2" />
    <child
      link="link3" />
    <axis
      xyz="0 0 1" />
    <limit
      lower="-1.5708"
      upper="1.5708"
      effort="0"
      velocity="0" />
  </joint>
  <link
    name="link4">
    <inertial>
      <origin
        xyz="-0.0028126 0.066034 -0.029727"
        rpy="0 0 0" />
      <mass
        value="0.046897" />
      <inertia
        ixx="3.8337E-05"
        ixy="1.0617E-06"
        ixz="-2.9932E-07"
        iyy="1.4304E-05"
        iyz="4.4588E-06"
        izz="2.8258E-05" />
    </inertial>
    <visual>
      <origin
        xyz="0 0 0"
        rpy="0 0 0" />
      <geometry>
        <mesh
          filename="package://arm_assembly_6/meshes/link4.STL" />
      </geometry>
      <material
        name="">
        <color
          rgba="0.79216 0.81961 0.93333 1" />
      </material>
    </visual>
    <collision>
      <origin
        xyz="0 0 0"
        rpy="0 0 0" />
      <geometry>
        <mesh
          filename="package://arm_assembly_6/meshes/link4.STL" />
      </geometry>
    </collision>
  </link>
  <joint
    name="joint4"
    type="revolute">
    <origin
      xyz="0.023994 -0.0033845 0.035099"
      rpy="1.5708 0 1.5691" />
    <parent
      link="link3" />
    <child
      link="link4" />
    <axis
      xyz="0 0 1" />
    <limit
      lower="-1.5708"
      upper="1.5708"
      effort="0"
      velocity="0" />
  </joint>
  <link
    name="link5">
    <inertial>
      <origin
        xyz="0.0051339 -0.0014331 0.035909"
        rpy="0 0 0" />
      <mass
        value="0.044197" />
      <inertia
        ixx="1.6768E-05"
        ixy="6.8764E-07"
        ixz="-9.2737E-07"
        iyy="1.6802E-05"
        iyz="3.3996E-07"
        izz="1.1763E-05" />
    </inertial>
    <visual>
      <origin
        xyz="0 0 0"
        rpy="0 0 0" />
      <geometry>
        <mesh
          filename="package://arm_assembly_6/meshes/link5.STL" />
      </geometry>
      <material
        name="">
        <color
          rgba="0.79216 0.81961 0.93333 1" />
      </material>
    </visual>
    <collision>
      <origin
        xyz="0 0 0"
        rpy="0 0 0" />
      <geometry>
        <mesh
          filename="package://arm_assembly_6/meshes/link5.STL" />
      </geometry>
    </collision>
  </link>
  <joint
    name="joint5"
    type="revolute">
    <origin
      xyz="-0.0023444 0.101 -0.022099"
      rpy="1.5708 1.5691 -3.1416" />
    <parent
      link="link4" />
    <child
      link="link5" />
    <axis
      xyz="0 0 1" />
    <limit
      lower="-1.5708"
      upper="1.5708"
      effort="0"
      velocity="0" />
  </joint>
  <link
    name="link6">
    <inertial>
      <origin
        xyz="-0.00042637 0.028181 -0.020504"
        rpy="0 0 0" />
      <mass
        value="0.009246" />
      <inertia
        ixx="9.4951E-06"
        ixy="5.5353E-08"
        ixz="-7.868E-09"
        iyy="5.8374E-06"
        iyz="5.2004E-07"
        izz="4.5813E-06" />
    </inertial>
    <visual>
      <origin
        xyz="0 0 0"
        rpy="0 0 0" />
      <geometry>
        <mesh
          filename="package://arm_assembly_6/meshes/link6.STL" />
      </geometry>
      <material
        name="">
        <color
          rgba="0.79216 0.81961 0.93333 1" />
      </material>
    </visual>
    <collision>
      <origin
        xyz="0 0 0"
        rpy="0 0 0" />
      <geometry>
        <mesh
          filename="package://arm_assembly_6/meshes/link6.STL" />
      </geometry>
    </collision>
  </link>
  <joint
    name="joint6"
    type="revolute">
    <origin
      xyz="0.0033864 0.023994 0.030099"
      rpy="1.5708 0.012103 3.1398" />
    <parent
      link="link5" />
    <child
      link="link6" />
    <axis
      xyz="0 0 1" />
    <limit
      lower="-1.5708"
      upper="1.5708"
      effort="0"
      velocity="0" />
  </joint>
</robot>
