<?xml version="1.0" encoding="utf-8"?>
<!-- This URDF was automatically created by SolidWorks to URDF Exporter! Originally created by Stephen Brawner (brawner@gmail.com) 
     Commit Version: 1.6.0-1-g15f4949  Build Version: 1.6.7594.29634
     For more information, please see http://wiki.ros.org/sw_urdf_exporter -->
<robot
  name="arm_assembly_2">
  <link
    name="link1">
    <inertial>
      <origin
        xyz="1.1338E-06 9.9819E-06 -0.020292"
        rpy="0 0 0" />
      <mass
        value="0.031905" />
      <inertia
        ixx="8.6771E-06"
        ixy="-2.6656E-10"
        ixz="9.1152E-11"
        iyy="5.2647E-06"
        iyz="8.0892E-08"
        izz="5.4828E-06" />
    </inertial>
    <visual>
      <origin
        xyz="0 0 0"
        rpy="0 0 0" />
      <geometry>
        <mesh
          filename="package://arm_assembly_2/meshes/link1.STL" />
      </geometry>
      <material
        name="">
        <color
          rgba="0.79216 0.81961 0.93333 1" />
      </material>
    </visual>
    <collision>
      <origin
        xyz="0 0 0"
        rpy="0 0 0" />
      <geometry>
        <mesh
          filename="package://arm_assembly_2/meshes/link1.STL" />
      </geometry>
    </collision>
  </link>
  <link
    name="link2">
    <inertial>
      <origin
        xyz="-0.0087141 0.0060617 -0.028002"
        rpy="0 0 0" />
      <mass
        value="0.04101" />
      <inertia
        ixx="9.4593E-06"
        ixy="3.7131E-07"
        ixz="-5.3734E-07"
        iyy="9.1892E-06"
        iyz="5.2146E-07"
        izz="1.2798E-05" />
    </inertial>
    <visual>
      <origin
        xyz="0 0 0"
        rpy="0 0 0" />
      <geometry>
        <mesh
          filename="package://arm_assembly_2/meshes/link2.STL" />
      </geometry>
      <material
        name="">
        <color
          rgba="0.79216 0.81961 0.93333 1" />
      </material>
    </visual>
    <collision>
      <origin
        xyz="0 0 0"
        rpy="0 0 0" />
      <geometry>
        <mesh
          filename="package://arm_assembly_2/meshes/link2.STL" />
      </geometry>
    </collision>
  </link>
  <joint
    name="joint1"
    type="continuous">
    <origin
      xyz="0.00015556 0.0099012 -0.0435"
      rpy="0 0 0" />
    <parent
      link="link1" />
    <child
      link="link2" />
    <axis
      xyz="0 0 -1" />
  </joint>
  <link
    name="link3">
    <inertial>
      <origin
        xyz="-0.002309 0.035492 -0.043342"
        rpy="0 0 0" />
      <mass
        value="0.044197" />
      <inertia
        ixx="3.3418E-05"
        ixy="3.9532E-07"
        ixz="-5.011E-07"
        iyy="2.4892E-05"
        iyz="7.3143E-06"
        izz="1.2384E-05" />
    </inertial>
    <visual>
      <origin
        xyz="0 0 0"
        rpy="0 0 0" />
      <geometry>
        <mesh
          filename="package://arm_assembly_2/meshes/link3.STL" />
      </geometry>
      <material
        name="">
        <color
          rgba="0.79216 0.81961 0.93333 1" />
      </material>
    </visual>
    <collision>
      <origin
        xyz="0 0 0"
        rpy="0 0 0" />
      <geometry>
        <mesh
          filename="package://arm_assembly_2/meshes/link3.STL" />
      </geometry>
    </collision>
  </link>
  <joint
    name="joint2"
    type="continuous">
    <origin
      xyz="0.00040116 0.032139 -0.028656"
      rpy="0 0 0" />
    <parent
      link="link2" />
    <child
      link="link3" />
    <axis
      xyz="0 -1 0" />
  </joint>
  <link
    name="link4">
    <inertial>
      <origin
        xyz="-0.0013421 0.0048708 -0.042547"
        rpy="0 0 0" />
      <mass
        value="0.046897" />
      <inertia
        ixx="2.1057E-05"
        ixy="7.0643E-07"
        ixz="-3.4862E-07"
        iyy="1.9127E-05"
        iyz="9.7052E-07"
        izz="1.3946E-05" />
    </inertial>
    <visual>
      <origin
        xyz="0 0 0"
        rpy="0 0 0" />
      <geometry>
        <mesh
          filename="package://arm_assembly_2/meshes/link4.STL" />
      </geometry>
      <material
        name="">
        <color
          rgba="0.79216 0.81961 0.93333 1" />
      </material>
    </visual>
    <collision>
      <origin
        xyz="0 0 0"
        rpy="0 0 0" />
      <geometry>
        <mesh
          filename="package://arm_assembly_2/meshes/link4.STL" />
      </geometry>
    </collision>
  </link>
  <joint
    name="joint3"
    type="continuous">
    <origin
      xyz="-0.0014881 0.02946 -0.074719"
      rpy="0 0 0" />
    <parent
      link="link3" />
    <child
      link="link4" />
    <axis
      xyz="0 0 1" />
  </joint>
  <link
    name="link5">
    <inertial>
      <origin
        xyz="-0.0057267 0.002757 -0.066036"
        rpy="0 0 0" />
      <mass
        value="0.046897" />
      <inertia
        ixx="2.8258E-05"
        ixy="2.9557E-07"
        ixz="-4.4591E-06"
        iyy="3.8338E-05"
        iyz="1.0415E-06"
        izz="1.4302E-05" />
    </inertial>
    <visual>
      <origin
        xyz="0 0 0"
        rpy="0 0 0" />
      <geometry>
        <mesh
          filename="package://arm_assembly_2/meshes/link5.STL" />
      </geometry>
      <material
        name="">
        <color
          rgba="0.79216 0.81961 0.93333 1" />
      </material>
    </visual>
    <collision>
      <origin
        xyz="0 0 0"
        rpy="0 0 0" />
      <geometry>
        <mesh
          filename="package://arm_assembly_2/meshes/link5.STL" />
      </geometry>
    </collision>
  </link>
  <joint
    name="joint4"
    type="continuous">
    <origin
      xyz="0 0.0033706 -0.036909"
      rpy="0 0 0" />
    <parent
      link="link4" />
    <child
      link="link5" />
    <axis
      xyz="-1 0 0" />
  </joint>
  <link
    name="link6">
    <inertial>
      <origin
        xyz="-0.0051364 -0.001456 -0.037837"
        rpy="0 0 0" />
      <mass
        value="0.044197" />
      <inertia
        ixx="1.6766E-05"
        ixy="-6.8836E-07"
        ixz="-9.2738E-07"
        iyy="1.6803E-05"
        iyz="-3.4259E-07"
        izz="1.1763E-05" />
    </inertial>
    <visual>
      <origin
        xyz="0 0 0"
        rpy="0 0 0" />
      <geometry>
        <mesh
          filename="package://arm_assembly_2/meshes/link6.STL" />
      </geometry>
      <material
        name="">
        <color
          rgba="0.79216 0.81961 0.93333 1" />
      </material>
    </visual>
    <collision>
      <origin
        xyz="0 0 0"
        rpy="0 0 0" />
      <geometry>
        <mesh
          filename="package://arm_assembly_2/meshes/link6.STL" />
      </geometry>
    </collision>
  </link>
  <joint
    name="joint5"
    type="continuous">
    <origin
      xyz="0.0019012 0.0022611 -0.099072"
      rpy="0 0 0" />
    <parent
      link="link5" />
    <child
      link="link6" />
    <axis
      xyz="0 0 1" />
  </joint>
  <link
    name="link7">
    <inertial>
      <origin
        xyz="-0.00344363220813368 0.00347221820362538 -0.027976126548721"
        rpy="0 0 0" />
      <mass
        value="0.00924604523543892" />
      <inertia
        ixx="9.44134996862413E-06"
        ixy="-6.3921133213713E-08"
        ixz="-4.43711954461436E-07"
        iyy="4.58042053560908E-06"
        iyz="-5.15095220793115E-07"
        izz="5.89206814135351E-06" />
    </inertial>
    <visual>
      <origin
        xyz="0 0 0"
        rpy="0 0 0" />
      <geometry>
        <mesh
          filename="package://arm_assembly_2/meshes/link7.STL" />
      </geometry>
      <material
        name="">
        <color
          rgba="0.792156862745098 0.819607843137255 0.933333333333333 1" />
      </material>
    </visual>
    <collision>
      <origin
        xyz="0 0 0"
        rpy="0 0 0" />
      <geometry>
        <mesh
          filename="package://arm_assembly_2/meshes/link7.STL" />
      </geometry>
    </collision>
  </link>
  <joint
    name="joint6"
    type="continuous">
    <origin
      xyz="-0.0033444 -2.7019E-05 -0.032028"
      rpy="0 0 0" />
    <parent
      link="link6" />
    <child
      link="link7" />
    <axis
      xyz="0 -1 0" />
  </joint>
</robot>