<?xml version="1.0" encoding="utf-8"?>
<!-- This URDF was automatically created by SolidWorks to URDF Exporter! Originally created by Stephen Brawner (brawner@gmail.com) 
     Commit Version: 1.6.0-1-g15f4949  Build Version: 1.6.7594.29634
     For more information, please see http://wiki.ros.org/sw_urdf_exporter -->
<robot
  name="arm_assembly_3">
  <link
    name="base_link">
    <inertial>
      <origin
        xyz="0.00537914192717504 -0.0200099819447371 -0.0202923199399593"
        rpy="0 0 0" />
      <mass
        value="0.0319051544349151" />
      <inertia
        ixx="8.67708325062344E-06"
        ixy="-2.66559260574462E-10"
        ixz="-9.11524933844445E-11"
        iyy="5.26472342333194E-06"
        iyz="-8.0891965519516E-08"
        izz="5.4827831046489E-06" />
    </inertial>
    <visual>
      <origin
        xyz="0 0 0"
        rpy="0 0 0" />
      <geometry>
        <mesh
          filename="package://arm_assembly_3/meshes/base_link.STL" />
      </geometry>
      <material
        name="">
        <color
          rgba="0.792156862745098 0.819607843137255 0.933333333333333 1" />
      </material>
    </visual>
    <collision>
      <origin
        xyz="0 0 0"
        rpy="0 0 0" />
      <geometry>
        <mesh
          filename="package://arm_assembly_3/meshes/base_link.STL" />
      </geometry>
    </collision>
  </link>
  <link
    name="link1">
    <inertial>
      <origin
        xyz="0.0085665233556407 -0.00626847506104749 -0.0270017173430756"
        rpy="0 0 0" />
      <mass
        value="0.0410104436802228" />
      <inertia
        ixx="9.47690608514341E-06"
        ixy="3.64423331475411E-07"
        ixz="5.24709186672203E-07"
        iyy="9.17156321907187E-06"
        iyz="-5.34168078377187E-07"
        izz="1.27983563828142E-05" />
    </inertial>
    <visual>
      <origin
        xyz="0 0 0"
        rpy="0 0 0" />
      <geometry>
        <mesh
          filename="package://arm_assembly_3/meshes/link1.STL" />
      </geometry>
      <material
        name="">
        <color
          rgba="0.792156862745098 0.819607843137255 0.933333333333333 1" />
      </material>
    </visual>
    <collision>
      <origin
        xyz="0 0 0"
        rpy="0 0 0" />
      <geometry>
        <mesh
          filename="package://arm_assembly_3/meshes/link1.STL" />
      </geometry>
    </collision>
  </link>
  <joint
    name="joint1"
    type="revolute">
    <origin
      xyz="0.0052247 -0.029901 -0.0445"
      rpy="0 0 0" />
    <parent
      link="base_link" />
    <child
      link="link1" />
    <axis
      xyz="0 0 1" />
    <limit
      lower="-0.785398"
      upper="3.316126"
      effort="0"
      velocity="0" />
  </joint>
  <link
    name="link2">
    <inertial>
      <origin
        xyz="0.0433001816963551 0.00298602346887532 0.034630760987739"
        rpy="0 0 0" />
      <mass
        value="0.0441973162046589" />
      <inertia
        ixx="1.2404432131126E-05"
        ixy="-8.29537244327774E-07"
        ixz="-7.30720685832946E-06"
        iyy="3.33974522345599E-05"
        iyz="-5.09577042810609E-07"
        izz="2.48917614267323E-05" />
    </inertial>
    <visual>
      <origin
        xyz="0 0 0"
        rpy="0 0 0" />
      <geometry>
        <mesh
          filename="package://arm_assembly_3/meshes/link2.STL" />
      </geometry>
      <material
        name="">
        <color
          rgba="0.792156862745098 0.819607843137255 0.933333333333333 1" />
      </material>
    </visual>
    <collision>
      <origin
        xyz="0 0 0"
        rpy="0 0 0" />
      <geometry>
        <mesh
          filename="package://arm_assembly_3/meshes/link2.STL" />
      </geometry>
    </collision>
  </link>
  <joint
    name="joint2"
    type="revolute">
    <origin
      xyz="-0.0011908 -0.032981 -0.027656"
      rpy="1.5947 1.5708 0" />
    <parent
      link="link1" />
    <child
      link="link2" />
    <axis
      xyz="0 0 -1" />
    <limit
      lower="-3.926991"
      upper="0.785398"
      effort="0"
      velocity="0" />
  </joint>
  <link
    name="link3">
    <inertial>
      <origin
        xyz="0.00144856709719526 -0.00480989017520077 -0.0407373019398186"
        rpy="0 0 0" />
      <mass
        value="0.0468973470900495" />
      <inertia
        ixx="2.1024763330585E-05"
        ixy="7.48036478819629E-07"
        ixz="3.70368656713493E-07"
        iyy="1.91604564254077E-05"
        iyz="-9.58910812954483E-07"
        izz="1.39446199408151E-05" />
    </inertial>
    <visual>
      <origin
        xyz="0 0 0"
        rpy="0 0 0" />
      <geometry>
        <mesh
          filename="package://arm_assembly_3/meshes/link3.STL" />
      </geometry>
      <material
        name="">
        <color
          rgba="0.792156862745098 0.819607843137255 0.933333333333333 1" />
      </material>
    </visual>
    <collision>
      <origin
        xyz="0 0 0"
        rpy="0 0 0" />
      <geometry>
        <mesh
          filename="package://arm_assembly_3/meshes/link3.STL" />
      </geometry>
    </collision>
  </link>
  <joint
    name="joint3"
    type="revolute">
    <origin
      xyz="0.0765 0.0026556 0.028599"
      rpy="-1.5708 0.023935 1.5708" />
    <parent
      link="link2" />
    <child
      link="link3"/>
    <axis
      xyz="0 0 1" />
    <limit
      lower="-1.745329"
      upper="1.745329"
      effort="0"
      velocity="0" />
  </joint>
  <link
    name="link4">
    <inertial>
      <origin
        xyz="0.000644251052055803 0.0660807451013709 0.0297482009756613"
        rpy="0 0 0" />
      <mass
        value="0.0468973133508552" />
      <inertia
        ixx="3.83763157971716E-05"
        ixy="-4.12052356248878E-07"
        ixz="2.6118586537159E-08"
        iyy="1.4268206807337E-05"
        iyz="-4.47467575685872E-06"
        izz="2.82540176065191E-05" />
    </inertial>
    <visual>
      <origin
        xyz="0 0 0"
        rpy="0 0 0" />
      <geometry>
        <mesh
          filename="package://arm_assembly_3/meshes/link4.STL" />
      </geometry>
      <material
        name="">
        <color
          rgba="0.792156862745098 0.819607843137255 0.933333333333333 1" />
      </material>
    </visual>
    <collision>
      <origin
        xyz="0 0 0"
        rpy="0 0 0" />
      <geometry>
        <mesh
          filename="package://arm_assembly_3/meshes/link4.STL" />
      </geometry>
    </collision>
  </link>
  <joint
    name="joint4"
    type="revolute">
    <origin
      xyz="-0.02392 -0.0038731 -0.035099"
      rpy="-1.5708 0 -1.5708" />
    <parent
      link="link3" />
    <child
      link="link4" />
    <axis
      xyz="-0.022063 0 0.99976" />
    <limit
      lower="-2.094395"
      upper="2.356194"
      effort="0"
      velocity="0" />
  </joint>
  <link
    name="link5">
    <inertial>
      <origin
        xyz="-0.00532701471353565 0.000182953422074653 -0.0359086026675726"
        rpy="0 0 0" />
      <mass
        value="0.0441973483087565" />
      <inertia
        ixx="1.63757481245814E-05"
        ixy="-5.52870289608153E-07"
        ixz="-9.86724855795872E-07"
        iyy="1.71941634742263E-05"
        iyz="-4.42711290371809E-08"
        izz="1.17625028185318E-05" />
    </inertial>
    <visual>
      <origin
        xyz="0 0 0"
        rpy="0 0 0" />
      <geometry>
        <mesh
          filename="package://arm_assembly_3/meshes/link5.STL" />
      </geometry>
      <material
        name="">
        <color
          rgba="0.792156862745098 0.819607843137255 0.933333333333333 1" />
      </material>
    </visual>
    <collision>
      <origin
        xyz="0 0 0"
        rpy="0 0 0" />
      <geometry>
        <mesh
          filename="package://arm_assembly_3/meshes/link5.STL" />
      </geometry>
    </collision>
  </link>
  <joint
    name="joint5"
    type="revolute">
    <origin
      xyz="-0.00045549 0.10103 0.022094"
      rpy="-0.022885 1.5703 -1.5708" />
    <parent
      link="link4" />
    <child
      link="link5" />
    <axis
      xyz="0 0 1" />
    <limit
      lower="-1.570796"
      upper="2.356194"
      effort="0"
      velocity="0" />
  </joint>
  <link
    name="link6">
    <inertial>
      <origin
        xyz="0.027917364247385 0.00387021844402496 0.0205041823015297"
        rpy="0 0 0" />
      <mass
        value="0.00924604523543896" />
      <inertia
        ixx="5.90557115471928E-06"
        ixy="-4.9774273116807E-07"
        ixz="-5.1517086793019E-07"
        iyy="9.42697695087516E-06"
        iyz="-7.14187692426848E-08"
        izz="4.58129053999237E-06" />
    </inertial>
    <visual>
      <origin
        xyz="0 0 0"
        rpy="0 0 0" />
      <geometry>
        <mesh
          filename="package://arm_assembly_3/meshes/link6.STL" />
      </geometry>
      <material
        name="">
        <color
          rgba="0.792156862745098 0.819607843137255 0.933333333333333 1" />
      </material>
    </visual>
    <collision>
      <origin
        xyz="0 0 0"
        rpy="0 0 0" />
      <geometry>
        <mesh
          filename="package://arm_assembly_3/meshes/link6.STL" />
      </geometry>
    </collision>
  </link>
  <joint
    name="joint6"
    type="revolute">
    <origin
      xyz="0.004012 0.023897 -0.030099"
      rpy="-1.5708 1.4947 2.8368" />
    <parent
      link="link5" />
    <child
      link="link6" />
    <axis
      xyz="0 0 1" />
    <limit
      lower="-1.570796"
      upper="1.570796"
      effort="0"
      velocity="0" />
  </joint>
</robot>
